Workbook
Name Compound_Application_NMR_214: 'compound numbers'!$A$129
Name Compound_comp07b_1324_939_cdcl3_45: 'compound numbers'!$A$159

Sheet OL-JOC - DOI details-from-figsh
A1: Index | B1: acscode | C1: #TODO.txt | D1: JavaIndex | E1: multiple | F1: SKIP | G1: status | H1: cmp | I1: spec | J1: struc | M1: // javaLine | N1: non-zip sup file | O1: rejected | P1: dataURL | Q1: SI DOI | R1: SI ext | S1: Article | T1: Aticle Title | U1: pubDOI | V1: acscode | W1: zip file name | X1: dataURL list | Y1: ="--localSource c:/temp/acs2/data --targetDir c:/temp/acs2/$DOI$ --noDownload --readOnly " -> --localSource c:/temp/acs2/data --targetDir c:/temp/acs2/$DOI$ --noDownload --readOnly | Z1: acs2.html | AA1: rejected as zip | AB1: rejected file name
A2: 1 | B2: =V2 -> jo4c02089 | C2: =IF(Y2="","",IF(OR(O2,F2=1,M2=""),"#"&B2 &" "&G2,B2&IF(G2="",""," # " &G2))) -> jo4c02089 | D2: =A2 - SUM(E$2:E2) -> 1 | E2: =IF(B2=B1,"1","0") -> 0 | F2: 0 | H2: 38 | I2: 75 | M2: =IF(OR(O2,D2=""),"","/*"&D2&" " & B2 &" */"""&Q2&""",//"&T2) -> /*1 jo4c02089 */"https://doi.org/10.1021/acs.joc.4c02089.s002",//Ring-Size-Dependent Selectivity of the β‑Hydride Elimination in Heck-Type Arylations of exo-Methylene Cycloketones: Chalcones versus 2‑Benzyl-1-naphthols | N2: =VLOOKUP(W2,AA:AB,2,FALSE) -> #N/A | O2: =NOT(ISNA(VLOOKUP(W2,AA:AA,1,FALSE))) -> FALSE | P2: https://acs.figshare.com/articles/dataset/Ring-Size-Dependent_Selectivity_of_the_Hydride_Elimination_in_Heck-Type_Arylations_of_i_exo_i_-Methylene_Cycloketones_Chalcones_versus_2_Benzyl-1-naphthols/28667362 | Q2: https://doi.org/10.1021/acs.joc.4c02089.s002 | R2: =MID(Q2,LEN(Q2)-2,4) -> 002 | S2: 1 | T2: =VLOOKUP(Q2,original!B:C,2,FALSE) -> Ring-Size-Dependent Selectivity of the β‑Hydride Elimination in Heck-Type Arylations of exo-Methylene Cycloketones: Chalcones versus 2‑Benzyl-1-naphthols | U2: https://doi.org/10.1021/acs.joc.4c02089 | V2: =SUBSTITUTE(SUBSTITUTE(MID(U2,LEN(U2)-8,100),"c.","jo"),"t.","ol") -> jo4c02089 | W2: =B2&"_si_"&R2&".zip" -> jo4c02089_si_002.zip | X2: =IF(U2<>U1,P2,X1&"\t"&P2) -> https://acs.figshare.com/articles/dataset/Ring-Size-Dependent_Selectivity_of_the_Hydride_Elimination_in_Heck-Type_Arylations_of_i_exo_i_-Methylene_Cycloketones_Chalcones_versus_2_Benzyl-1-naphthols/28667362 | Y2: =IF(U2<>U3,$Y$1&" --pubDOI "& U2&" --dataURL """&SUBSTITUTE(U2&X2&"""","https://doi.org/",""),"") -> --localSource c:/temp/acs2/data --targetDir c:/temp/acs2/$DOI$ --noDownload --readOnly --pubDOI https://doi.org/10.1021/acs.joc.4c02089 --dataURL "10.1021/acs.joc.4c02089https://acs.figshare.com/articles/dataset/Ring-Size-Dependent_Selectivity_of_the_Hydride_Elimination_in_Heck-Type_Arylations_of_i_exo_i_-Methylene_Cycloketones_Chalcones_versus_2_Benzyl-1-naphthols/28667362" | Z2: ="<br><a href="""&Q2&""">"&Q2&"</a>" -> <br><a href="https://doi.org/10.1021/acs.joc.4c02089.s002">https://doi.org/10.1021/acs.joc.4c02089.s002</a> | AA2: =IF(AB2="","",MID(AB2,1,LEN(AB2)-4)&".zip") -> jo5c01560_si_002.zip | AB2: jo5c01560_si_002.xyz
A3: 2 | B3: =V3 -> jo4c02094 | C3: =IF(Y3="","",IF(OR(O3,F3=1,M3=""),"#"&B3 &" "&G3,B3&IF(G3="",""," # " &G3))) | D3: =IF(F3=1,"",IF(AND(D2="",S2=S3),"",S3-SUM(F$2:F2))) -> 2 | E3: =IF(B3=B2,"1","0") -> 0 | F3: 0 | G3: fails [F-NMR, 3w, 10, pdata] F-NMR | M3: =IF(OR(O3,D3=""),"","/*"&D3&" " & B3 &" */"""&Q3&""",//"&T3) -> /*2 jo4c02094 */"https://doi.org/10.1021/acs.joc.4c02094.s002",//Meta-, Regioselective Amination of Cyclic Diaryliodoniums through C–I and C–O Bond Cleavages: An Access to Functionalized Coumarins | N3: =VLOOKUP(W3,AA:AB,2,FALSE) -> #N/A | O3: =NOT(ISNA(VLOOKUP(W3,AA:AA,1,FALSE))) -> FALSE | P3: https://acs.figshare.com/articles/dataset/_i_Meta_i_-_Regioselective_Amination_of_Cyclic_Diaryliodoniums_through_C_I_and_C_O_Bond_Cleavages_An_Access_to_Functionalized_Coumarins/28503207 | Q3: https://doi.org/10.1021/acs.joc.4c02094.s002 | R3: =MID(Q3,LEN(Q3)-2,4) -> 002 | S3: =IF(U3=U2,S2,S2+1) -> 2 | T3: =VLOOKUP(Q3,original!B:C,2,FALSE) -> Meta-, Regioselective Amination of Cyclic Diaryliodoniums through C–I and C–O Bond Cleavages: An Access to Functionalized Coumarins | U3: https://doi.org/10.1021/acs.joc.4c02094 | V3: =SUBSTITUTE(SUBSTITUTE(MID(U3,LEN(U3)-8,100),"c.","jo"),"t.","ol") -> jo4c02094 | W3: =B3&"_si_"&R3&".zip" -> jo4c02094_si_002.zip | X3: =IF(U3<>U2,P3,X2&"\t"&P3) -> https://acs.figshare.com/articles/dataset/_i_Meta_i_-_Regioselective_Amination_of_Cyclic_Diaryliodoniums_through_C_I_and_C_O_Bond_Cleavages_An_Access_to_Functionalized_Coumarins/28503207 | Y3: =IF(U3<>U4,$Y$1&" --pubDOI "& U3&" --dataDOI """&SUBSTITUTE(U3&X3&"""","https://doi.org/",""),"") | Z3: ="<br><a href="""&Q3&""">"&Q3&"</a>" -> <br><a href="https://doi.org/10.1021/acs.joc.4c02094.s002">https://doi.org/10.1021/acs.joc.4c02094.s002</a> | AA3: =IF(AB3="","",MID(AB3,1,LEN(AB3)-4)&".zip") -> jo4c02574_si_002.zip | AB3: jo4c02574_si_002.xls
A4: 3 | B4: =V4 -> jo4c02094 | C4: =IF(Y4="","",IF(OR(O4,F4=1,M4=""),"#"&B4 &" "&G4,B4&IF(G4="",""," # " &G4))) | D4: =IF(F4=1,"",IF(AND(D3="",S3=S4),"",S4-SUM(F$2:F3))) -> 2 | E4: =IF(B4=B3,"1","0") -> 1 | F4: 0 | G4: fails [F-NMR, 3w, 10, pdata] F-NMR | M4: =IF(OR(O4,D4=""),"","/*"&D4&" " & B4 &" */"""&Q4&""",//"&T4) -> /*2 jo4c02094 */"https://doi.org/10.1021/acs.joc.4c02094.s003",//Meta-, Regioselective Amination of Cyclic Diaryliodoniums through C–I and C–O Bond Cleavages: An Access to Functionalized Coumarins | N4: =VLOOKUP(W4,AA:AB,2,FALSE) -> #N/A | O4: =NOT(ISNA(VLOOKUP(W4,AA:AA,1,FALSE))) -> FALSE | P4: https://acs.figshare.com/articles/dataset/_i_Meta_i_-_Regioselective_Amination_of_Cyclic_Diaryliodoniums_through_C_I_and_C_O_Bond_Cleavages_An_Access_to_Functionalized_Coumarins/28503210 | Q4: https://doi.org/10.1021/acs.joc.4c02094.s003 | R4: =MID(Q4,LEN(Q4)-2,4) -> 003 | S4: =IF(U4=U3,S3,S3+1) -> 2 | T4: =VLOOKUP(Q4,original!B:C,2,FALSE) -> Meta-, Regioselective Amination of Cyclic Diaryliodoniums through C–I and C–O Bond Cleavages: An Access to Functionalized Coumarins | U4: https://doi.org/10.1021/acs.joc.4c02094 | V4: =SUBSTITUTE(SUBSTITUTE(MID(U4,LEN(U4)-8,100),"c.","jo"),"t.","ol") -> jo4c02094 | W4: =B4&"_si_"&R4&".zip" -> jo4c02094_si_003.zip | X4: =IF(U4<>U3,P4,X3&"\t"&P4) -> https://acs.figshare.com/articles/dataset/_i_Meta_i_-_Regioselective_Amination_of_Cyclic_Diaryliodoniums_through_C_I_and_C_O_Bond_Cleavages_An_Access_to_Functionalized_Coumarins/28503207\thttps://acs.figshare.com/articles/dataset/_i_Meta_i_-_Regioselective_Amination_of_Cyclic_Diaryliodoniums_through_C_I_and_C_O_Bond_Cleavages_An_Access_to_Functionalized_Coumarins/28503210 | Y4: =IF(U4<>U5,$Y$1&" --pubDOI "& U4&" --dataDOI """&SUBSTITUTE(U4&X4&"""","https://doi.org/",""),"") | Z4: ="<br><a href="""&Q4&""">"&Q4&"</a>" -> <br><a href="https://doi.org/10.1021/acs.joc.4c02094.s003">https://doi.org/10.1021/acs.joc.4c02094.s003</a> | AA4: =IF(AB4="","",MID(AB4,1,LEN(AB4)-4)&".zip") -> jo4c02676_si_001.zip | AB4: jo4c02676_si_001.xls
A5: 4 | B5: =V5 -> jo4c02094 | C5: =IF(Y5="","",IF(OR(O5,F5=1,M5=""),"#"&B5 &" "&G5,B5&IF(G5="",""," # " &G5))) -> jo4c02094 # fails [F-NMR, 3w, 10, pdata] F-NMR | D5: =IF(F5=1,"",IF(AND(D4="",S4=S5),"",S5-SUM(F$2:F4))) -> 2 | E5: =IF(B5=B4,"1","0") -> 1 | F5: 0 | G5: fails [F-NMR, 3w, 10, pdata] F-NMR | H5: 90 | I5: 143 | M5: =IF(OR(O5,D5=""),"","/*"&D5&" " & B5 &" */"""&Q5&""",//"&T5) -> /*2 jo4c02094 */"https://doi.org/10.1021/acs.joc.4c02094.s004",//<i>Meta</i>-, Regioselective Amination of Cyclic Diaryliodoniums through C–I and C–O Bond Cleavages: An Access to Functionalized Coumarins | N5: =VLOOKUP(W5,AA:AB,2,FALSE) -> #N/A | O5: =NOT(ISNA(VLOOKUP(W5,AA:AA,1,FALSE))) -> FALSE | P5: https://acs.figshare.com/articles/dataset/_i_Meta_i_-_Regioselective_Amination_of_Cyclic_Diaryliodoniums_through_C_I_and_C_O_Bond_Cleavages_An_Access_to_Functionalized_Coumarins/28503213 | Q5: https://doi.org/10.1021/acs.joc.4c02094.s004 | R5: =MID(Q5,LEN(Q5)-2,4) -> 004 | S5: =IF(U5=U4,S4,S4+1) -> 2 | T5: =VLOOKUP(Q5,original!B:C,2,FALSE) -> <i>Meta</i>-, Regioselective Amination of Cyclic Diaryliodoniums through C–I and C–O Bond Cleavages: An Access to Functionalized Coumarins | U5: https://doi.org/10.1021/acs.joc.4c02094 | V5: =SUBSTITUTE(SUBSTITUTE(MID(U5,LEN(U5)-8,100),"c.","jo"),"t.","ol") -> jo4c02094 | W5: =B5&"_si_"&R5&".zip" -> jo4c02094_si_004.zip | X5: =IF(U5<>U4,P5,X4&"\t"&P5) -> https://acs.figshare.com/articles/dataset/_i_Meta_i_-_Regioselective_Amination_of_Cyclic_Diaryliodoniums_through_C_I_and_C_O_Bond_Cleavages_An_Access_to_Functionalized_Coumarins/28503207\thttps://acs.figshare.com/articles/dataset/_i_Meta_i_-_Regioselective_Amination_of_Cyclic_Diaryliodoniums_through_C_I_and_C_O_Bond_Cleavages_An_Access_to_Functionalized_Coumarins/28503210\thttps://acs.figshare.com/articles/dataset/_i_Meta_i_-_Regioselective_Amination_of_Cyclic_Diaryliodoniums_through_C_I_and_C_O_Bond_Cleavages_An_Access_to_Functionalized_Coumarins/28503213 | Y5: =IF(U5<>U6,$Y$1&" --pubDOI "& U5&" --dataDOI """&SUBSTITUTE(U5&X5&"""","https://doi.org/",""),"") -> --localSource c:/temp/acs2/data --targetDir c:/temp/acs2/$DOI$ --noDownload --readOnly --pubDOI https://doi.org/10.1021/acs.joc.4c02094 --dataDOI "10.1021/acs.joc.4c02094https://acs.figshare.com/articles/dataset/_i_Meta_i_-_Regioselective_Amination_of_Cyclic_Diaryliodoniums_through_C_I_and_C_O_Bond_Cleavages_An_Access_to_Functionalized_Coumarins/28503207\thttps://acs.figshare.com/articles/dataset/_i_Meta_i_-_Regioselective_Amination_of_Cyclic_Diaryliodoniums_through_C_I_and_C_O_Bond_Cleavages_An_Access_to_Functionalized_Coumarins/28503210\thttps://acs.figshare.com/articles/dataset/_i_Meta_i_-_Regioselective_Amination_of_Cyclic_Diaryliodoniums_through_C_I_and_C_O_Bond_Cleavages_An_Access_to_Functionalized_Coumarins/28503213" | Z5: ="<br><a href="""&Q5&""">"&Q5&"</a>" -> <br><a href="https://doi.org/10.1021/acs.joc.4c02094.s004">https://doi.org/10.1021/acs.joc.4c02094.s004</a> | AA5: =IF(AB5="","",MID(AB5,1,LEN(AB5)-4)&".zip") -> jo5c00172_si_002.zip | AB5: jo5c00172_si_002.xyz
A6: 5 | B6: =V6 -> jo4c02335 | C6: =IF(Y6="","",IF(OR(O6,F6=1,M6=""),"#"&B6 &" "&G6,B6&IF(G6="",""," # " &G6))) -> jo4c02335 | D6: =IF(F6=1,"",IF(AND(D5="",S5=S6),"",S6-SUM(F$2:F5))) -> 3 | E6: =IF(B6=B5,"1","0") -> 0 | F6: 0 | H6: 72 | I6: 73 | M6: =IF(OR(O6,D6=""),"","/*"&D6&" " & B6 &" */"""&Q6&""",//"&T6) -> /*3 jo4c02335 */"https://doi.org/10.1021/acs.joc.4c02335.s002",//TEMPO-Mediated Direct C(sp2)–H Alkoxylation/Aryloxylation of 1,4-Quinones | N6: =VLOOKUP(W6,AA:AB,2,FALSE) -> #N/A | O6: =NOT(ISNA(VLOOKUP(W6,AA:AA,1,FALSE))) -> FALSE | P6: https://acs.figshare.com/articles/dataset/TEMPO-Mediated_Direct_C_sp_sup_2_sup_H_Alkoxylation_Aryloxylation_of_1_4-Quinones/28137633 | Q6: https://doi.org/10.1021/acs.joc.4c02335.s002 | R6: =MID(Q6,LEN(Q6)-2,4) -> 002 | S6: =IF(U6=U5,S5,S5+1) -> 3 | T6: =VLOOKUP(Q6,original!B:C,2,FALSE) -> TEMPO-Mediated Direct C(sp2)–H Alkoxylation/Aryloxylation of 1,4-Quinones | U6: https://doi.org/10.1021/acs.joc.4c02335 | V6: =SUBSTITUTE(SUBSTITUTE(MID(U6,LEN(U6)-8,100),"c.","jo"),"t.","ol") -> jo4c02335 | W6: =B6&"_si_"&R6&".zip" -> jo4c02335_si_002.zip | X6: =IF(U6<>U5,P6,X5&"\t"&P6) -> https://acs.figshare.com/articles/dataset/TEMPO-Mediated_Direct_C_sp_sup_2_sup_H_Alkoxylation_Aryloxylation_of_1_4-Quinones/28137633 | Y6: =IF(U6<>U7,$Y$1&" --pubDOI "& U6&" --dataDOI """&SUBSTITUTE(U6&X6&"""","https://doi.org/",""),"") -> --localSource c:/temp/acs2/data --targetDir c:/temp/acs2/$DOI$ --noDownload --readOnly --pubDOI https://doi.org/10.1021/acs.joc.4c02335 --dataDOI "10.1021/acs.joc.4c02335https://acs.figshare.com/articles/dataset/TEMPO-Mediated_Direct_C_sp_sup_2_sup_H_Alkoxylation_Aryloxylation_of_1_4-Quinones/28137633" | Z6: ="<br><a href="""&Q6&""">"&Q6&"</a>" -> <br><a href="https://doi.org/10.1021/acs.joc.4c02335.s002">https://doi.org/10.1021/acs.joc.4c02335.s002</a> | AA6: =IF(AB6="","",MID(AB6,1,LEN(AB6)-4)&".zip") -> jo5c00225_si_002.zip | AB6: jo5c00225_si_002.xyz
A7: 6 | B7: =V7 -> jo4c02429 | C7: =IF(Y7="","",IF(OR(O7,F7=1,M7=""),"#"&B7 &" "&G7,B7&IF(G7="",""," # " &G7))) -> jo4c02429 | D7: =IF(F7=1,"",IF(AND(D6="",S6=S7),"",S7-SUM(F$2:F6))) -> 4 | E7: =IF(B7=B6,"1","0") -> 0 | F7: 0 | H7: 1 | I7: 70 | J7: 1 | M7: =IF(OR(O7,D7=""),"","/*"&D7&" " & B7 &" */"""&Q7&""",//"&T7) -> /*4 jo4c02429 */"https://doi.org/10.1021/acs.joc.4c02429.s002",//Electrochemical Cyclization–Desulfurization Approach for the Synthesis of 1,3-Benzoxazines Using Cascade C–O and C–N Bond Formation | N7: =VLOOKUP(W7,AA:AB,2,FALSE) -> #N/A | O7: =NOT(ISNA(VLOOKUP(W7,AA:AA,1,FALSE))) -> FALSE | P7: https://acs.figshare.com/articles/dataset/Electrochemical_Cyclization_Desulfurization_Approach_for_the_Synthesis_of_1_3-Benzoxazines_Using_Cascade_C_O_and_C_N_Bond_Formation/28308688 | Q7: https://doi.org/10.1021/acs.joc.4c02429.s002 | R7: =MID(Q7,LEN(Q7)-2,4) -> 002 | S7: =IF(U7=U6,S6,S6+1) -> 4 | T7: =VLOOKUP(Q7,original!B:C,2,FALSE) -> Electrochemical Cyclization–Desulfurization Approach for the Synthesis of 1,3-Benzoxazines Using Cascade C–O and C–N Bond Formation | U7: https://doi.org/10.1021/acs.joc.4c02429 | V7: =SUBSTITUTE(SUBSTITUTE(MID(U7,LEN(U7)-8,100),"c.","jo"),"t.","ol") -> jo4c02429 | W7: =B7&"_si_"&R7&".zip" -> jo4c02429_si_002.zip | X7: =IF(U7<>U6,P7,X6&"\t"&P7) -> https://acs.figshare.com/articles/dataset/Electrochemical_Cyclization_Desulfurization_Approach_for_the_Synthesis_of_1_3-Benzoxazines_Using_Cascade_C_O_and_C_N_Bond_Formation/28308688 | Y7: =IF(U7<>U8,$Y$1&" --pubDOI "& U7&" --dataDOI """&SUBSTITUTE(U7&X7&"""","https://doi.org/",""),"") -> --localSource c:/temp/acs2/data --targetDir c:/temp/acs2/$DOI$ --noDownload --readOnly --pubDOI https://doi.org/10.1021/acs.joc.4c02429 --dataDOI "10.1021/acs.joc.4c02429https://acs.figshare.com/articles/dataset/Electrochemical_Cyclization_Desulfurization_Approach_for_the_Synthesis_of_1_3-Benzoxazines_Using_Cascade_C_O_and_C_N_Bond_Formation/28308688" | Z7: ="<br><a href="""&Q7&""">"&Q7&"</a>" -> <br><a href="https://doi.org/10.1021/acs.joc.4c02429.s002">https://doi.org/10.1021/acs.joc.4c02429.s002</a> | AA7: =IF(AB7="","",MID(AB7,1,LEN(AB7)-4)&".zip") -> jo5c00410_si_002.zip | AB7: jo5c00410_si_002.xyz
A8: 7 | B8: =V8 -> jo4c02450 | C8: =IF(Y8="","",IF(OR(O8,F8=1,M8=""),"#"&B8 &" "&G8,B8&IF(G8="",""," # " &G8))) | D8: =IF(F8=1,"",IF(AND(D7="",S7=S8),"",S8-SUM(F$2:F7))) -> 5 | E8: =IF(B8=B7,"1","0") -> 0 | F8: 0 | M8: =IF(OR(O8,D8=""),"","/*"&D8&" " & B8 &" */"""&Q8&""",//"&T8) -> /*5 jo4c02450 */"https://doi.org/10.1021/acs.joc.4c02450.s002",//Four Alkaloids from Alstonia scholaris with Antitumor Activity via Disturbing Glutathione Homeostasis | N8: =VLOOKUP(W8,AA:AB,2,FALSE) -> #N/A | O8: =NOT(ISNA(VLOOKUP(W8,AA:AA,1,FALSE))) -> FALSE | P8: https://acs.figshare.com/articles/dataset/Four_Alkaloids_from_i_Alstonia_scholaris_i_with_Antitumor_Activity_via_Disturbing_Glutathione_Homeostasis/28181963 | Q8: https://doi.org/10.1021/acs.joc.4c02450.s002 | R8: =MID(Q8,LEN(Q8)-2,4) -> 002 | S8: =IF(U8=U7,S7,S7+1) -> 5 | T8: =VLOOKUP(Q8,original!B:C,2,FALSE) -> Four Alkaloids from Alstonia scholaris with Antitumor Activity via Disturbing Glutathione Homeostasis | U8: https://doi.org/10.1021/acs.joc.4c02450 | V8: =SUBSTITUTE(SUBSTITUTE(MID(U8,LEN(U8)-8,100),"c.","jo"),"t.","ol") -> jo4c02450 | W8: =B8&"_si_"&R8&".zip" -> jo4c02450_si_002.zip | X8: =IF(U8<>U7,P8,X7&"\t"&P8) -> https://acs.figshare.com/articles/dataset/Four_Alkaloids_from_i_Alstonia_scholaris_i_with_Antitumor_Activity_via_Disturbing_Glutathione_Homeostasis/28181963 | Y8: =IF(U8<>U9,$Y$1&" --pubDOI "& U8&" --dataDOI """&SUBSTITUTE(U8&X8&"""","https://doi.org/",""),"") | Z8: ="<br><a href="""&Q8&""">"&Q8&"</a>" -> <br><a href="https://doi.org/10.1021/acs.joc.4c02450.s002">https://doi.org/10.1021/acs.joc.4c02450.s002</a> | AA8: =IF(AB8="","",MID(AB8,1,LEN(AB8)-4)&".zip") -> jo5c00670_si_001.zip | AB8: jo5c00670_si_001.xyz
A9: 8 | B9: =V9 -> jo4c02450 | C9: =IF(Y9="","",IF(OR(O9,F9=1,M9=""),"#"&B9 &" "&G9,B9&IF(G9="",""," # " &G9))) | D9: =IF(F9=1,"",IF(AND(D8="",S8=S9),"",S9-SUM(F$2:F8))) -> 5 | E9: =IF(B9=B8,"1","0") -> 1 | F9: 0 | M9: =IF(OR(O9,D9=""),"","/*"&D9&" " & B9 &" */"""&Q9&""",//"&T9) -> /*5 jo4c02450 */"https://doi.org/10.1021/acs.joc.4c02450.s003",//Four Alkaloids from Alstonia scholaris with Antitumor Activity via Disturbing Glutathione Homeostasis | N9: =VLOOKUP(W9,AA:AB,2,FALSE) -> #N/A | O9: =NOT(ISNA(VLOOKUP(W9,AA:AA,1,FALSE))) -> FALSE | P9: https://acs.figshare.com/articles/dataset/Four_Alkaloids_from_i_Alstonia_scholaris_i_with_Antitumor_Activity_via_Disturbing_Glutathione_Homeostasis/28181966 | Q9: https://doi.org/10.1021/acs.joc.4c02450.s003 | R9: =MID(Q9,LEN(Q9)-2,4) -> 003 | S9: =IF(U9=U8,S8,S8+1) -> 5 | T9: =VLOOKUP(Q9,original!B:C,2,FALSE) -> Four Alkaloids from Alstonia scholaris with Antitumor Activity via Disturbing Glutathione Homeostasis | U9: https://doi.org/10.1021/acs.joc.4c02450 | V9: =SUBSTITUTE(SUBSTITUTE(MID(U9,LEN(U9)-8,100),"c.","jo"),"t.","ol") -> jo4c02450 | W9: =B9&"_si_"&R9&".zip" -> jo4c02450_si_003.zip | X9: =IF(U9<>U8,P9,X8&"\t"&P9) -> https://acs.figshare.com/articles/dataset/Four_Alkaloids_from_i_Alstonia_scholaris_i_with_Antitumor_Activity_via_Disturbing_Glutathione_Homeostasis/28181963\thttps://acs.figshare.com/articles/dataset/Four_Alkaloids_from_i_Alstonia_scholaris_i_with_Antitumor_Activity_via_Disturbing_Glutathione_Homeostasis/28181966 | Y9: =IF(U9<>U10,$Y$1&" --pubDOI "& U9&" --dataDOI """&SUBSTITUTE(U9&X9&"""","https://doi.org/",""),"") | Z9: ="<br><a href="""&Q9&""">"&Q9&"</a>" -> <br><a href="https://doi.org/10.1021/acs.joc.4c02450.s003">https://doi.org/10.1021/acs.joc.4c02450.s003</a> | AA9: =IF(AB9="","",MID(AB9,1,LEN(AB9)-4)&".zip") -> jo5c00726_si_001.zip | AB9: jo5c00726_si_001.xyz
A10: 9 | B10: =V10 -> jo4c02450 | C10: =IF(Y10="","",IF(OR(O10,F10=1,M10=""),"#"&B10 &" "&G10,B10&IF(G10="",""," # " &G10))) | D10: =IF(F10=1,"",IF(AND(D9="",S9=S10),"",S10-SUM(F$2:F9))) -> 5 | E10: =IF(B10=B9,"1","0") -> 1 | F10: 0 | M10: =IF(OR(O10,D10=""),"","/*"&D10&" " & B10 &" */"""&Q10&""",//"&T10) -> /*5 jo4c02450 */"https://doi.org/10.1021/acs.joc.4c02450.s004",//Four Alkaloids from Alstonia scholaris with Antitumor Activity via Disturbing Glutathione Homeostasis | N10: =VLOOKUP(W10,AA:AB,2,FALSE) -> #N/A | O10: =NOT(ISNA(VLOOKUP(W10,AA:AA,1,FALSE))) -> FALSE | P10: https://acs.figshare.com/articles/dataset/Four_Alkaloids_from_i_Alstonia_scholaris_i_with_Antitumor_Activity_via_Disturbing_Glutathione_Homeostasis/28181969 | Q10: https://doi.org/10.1021/acs.joc.4c02450.s004 | R10: =MID(Q10,LEN(Q10)-2,4) -> 004 | S10: =IF(U10=U9,S9,S9+1) -> 5 | T10: =VLOOKUP(Q10,original!B:C,2,FALSE) -> Four Alkaloids from Alstonia scholaris with Antitumor Activity via Disturbing Glutathione Homeostasis | U10: https://doi.org/10.1021/acs.joc.4c02450 | V10: =SUBSTITUTE(SUBSTITUTE(MID(U10,LEN(U10)-8,100),"c.","jo"),"t.","ol") -> jo4c02450 | W10: =B10&"_si_"&R10&".zip" -> jo4c02450_si_004.zip | X10: =IF(U10<>U9,P10,X9&"\t"&P10) -> https://acs.figshare.com/articles/dataset/Four_Alkaloids_from_i_Alstonia_scholaris_i_with_Antitumor_Activity_via_Disturbing_Glutathione_Homeostasis/28181963\thttps://acs.figshare.com/articles/dataset/Four_Alkaloids_from_i_Alstonia_scholaris_i_with_Antitumor_Activity_via_Disturbing_Glutathione_Homeostasis/28181966\thttps://acs.figshare.com/articles/dataset/Four_Alkaloids_from_i_Alstonia_scholaris_i_with_Antitumor_Activity_via_Disturbing_Glutathione_Homeostasis/28181969 | Y10: =IF(U10<>U11,$Y$1&" --pubDOI "& U10&" --dataDOI """&SUBSTITUTE(U10&X10&"""","https://doi.org/",""),"") | Z10: ="<br><a href="""&Q10&""">"&Q10&"</a>" -> <br><a href="https://doi.org/10.1021/acs.joc.4c02450.s004">https://doi.org/10.1021/acs.joc.4c02450.s004</a> | AA10: =IF(AB10="","",MID(AB10,1,LEN(AB10)-4)&".zip") -> jo5c00744_si_002.zip | AB10: jo5c00744_si_002.xyz
A11: 10 | B11: =V11 -> jo4c02450 | C11: =IF(Y11="","",IF(OR(O11,F11=1,M11=""),"#"&B11 &" "&G11,B11&IF(G11="",""," # " &G11))) | D11: =IF(F11=1,"",IF(AND(D10="",S10=S11),"",S11-SUM(F$2:F10))) -> 5 | E11: =IF(B11=B10,"1","0") -> 1 | F11: 0 | M11: =IF(OR(O11,D11=""),"","/*"&D11&" " & B11 &" */"""&Q11&""",//"&T11) -> /*5 jo4c02450 */"https://doi.org/10.1021/acs.joc.4c02450.s005",//Four Alkaloids from Alstonia scholaris with Antitumor Activity via Disturbing Glutathione Homeostasis | N11: =VLOOKUP(W11,AA:AB,2,FALSE) -> #N/A | O11: =NOT(ISNA(VLOOKUP(W11,AA:AA,1,FALSE))) -> FALSE | P11: https://acs.figshare.com/articles/dataset/Four_Alkaloids_from_i_Alstonia_scholaris_i_with_Antitumor_Activity_via_Disturbing_Glutathione_Homeostasis/28181978 | Q11: https://doi.org/10.1021/acs.joc.4c02450.s005 | R11: =MID(Q11,LEN(Q11)-2,4) -> 005 | S11: =IF(U11=U10,S10,S10+1) -> 5 | T11: =VLOOKUP(Q11,original!B:C,2,FALSE) -> Four Alkaloids from Alstonia scholaris with Antitumor Activity via Disturbing Glutathione Homeostasis | U11: https://doi.org/10.1021/acs.joc.4c02450 | V11: =SUBSTITUTE(SUBSTITUTE(MID(U11,LEN(U11)-8,100),"c.","jo"),"t.","ol") -> jo4c02450 | W11: =B11&"_si_"&R11&".zip" -> jo4c02450_si_005.zip | X11: =IF(U11<>U10,P11,X10&"\t"&P11) -> https://acs.figshare.com/articles/dataset/Four_Alkaloids_from_i_Alstonia_scholaris_i_with_Antitumor_Activity_via_Disturbing_Glutathione_Homeostasis/28181963\thttps://acs.figshare.com/articles/dataset/Four_Alkaloids_from_i_Alstonia_scholaris_i_with_Antitumor_Activity_via_Disturbing_Glutathione_Homeostasis/28181966\thttps://acs.figshare.com/articles/dataset/Four_Alkaloids_from_i_Alstonia_scholaris_i_with_Antitumor_Activity_via_Disturbing_Glutathione_Homeostasis/28181969\thttps://acs.figshare.com/articles/dataset/Four_Alkaloids_from_i_Alstonia_scholaris_i_with_Antitumor_Activity_via_Disturbing_Glutathione_Homeostasis/28181978 | Y11: =IF(U11<>U12,$Y$1&" --pubDOI "& U11&" --dataDOI """&SUBSTITUTE(U11&X11&"""","https://doi.org/",""),"") | Z11: ="<br><a href="""&Q11&""">"&Q11&"</a>" -> <br><a href="https://doi.org/10.1021/acs.joc.4c02450.s005">https://doi.org/10.1021/acs.joc.4c02450.s005</a> | AA11: =IF(AB11="","",MID(AB11,1,LEN(AB11)-4)&".zip") -> jo5c00787_si_001.zip | AB11: jo5c00787_si_001.xyz
A12: 11 | B12: =V12 -> jo4c02450 | C12: =IF(Y12="","",IF(OR(O12,F12=1,M12=""),"#"&B12 &" "&G12,B12&IF(G12="",""," # " &G12))) | D12: =IF(F12=1,"",IF(AND(D11="",S11=S12),"",S12-SUM(F$2:F11))) -> 5 | E12: =IF(B12=B11,"1","0") -> 1 | F12: 0 | M12: =IF(OR(O12,D12=""),"","/*"&D12&" " & B12 &" */"""&Q12&""",//"&T12) -> /*5 jo4c02450 */"https://doi.org/10.1021/acs.joc.4c02450.s006",//Four Alkaloids from Alstonia scholaris with Antitumor Activity via Disturbing Glutathione Homeostasis | N12: =VLOOKUP(W12,AA:AB,2,FALSE) -> #N/A | O12: =NOT(ISNA(VLOOKUP(W12,AA:AA,1,FALSE))) -> FALSE | P12: https://acs.figshare.com/articles/dataset/Four_Alkaloids_from_i_Alstonia_scholaris_i_with_Antitumor_Activity_via_Disturbing_Glutathione_Homeostasis/28181990 | Q12: https://doi.org/10.1021/acs.joc.4c02450.s006 | R12: =MID(Q12,LEN(Q12)-2,4) -> 006 | S12: =IF(U12=U11,S11,S11+1) -> 5 | T12: =VLOOKUP(Q12,original!B:C,2,FALSE) -> Four Alkaloids from Alstonia scholaris with Antitumor Activity via Disturbing Glutathione Homeostasis | U12: https://doi.org/10.1021/acs.joc.4c02450 | V12: =SUBSTITUTE(SUBSTITUTE(MID(U12,LEN(U12)-8,100),"c.","jo"),"t.","ol") -> jo4c02450 | W12: =B12&"_si_"&R12&".zip" -> jo4c02450_si_006.zip | X12: =IF(U12<>U11,P12,X11&"\t"&P12) -> https://acs.figshare.com/articles/dataset/Four_Alkaloids_from_i_Alstonia_scholaris_i_with_Antitumor_Activity_via_Disturbing_Glutathione_Homeostasis/28181963\thttps://acs.figshare.com/articles/dataset/Four_Alkaloids_from_i_Alstonia_scholaris_i_with_Antitumor_Activity_via_Disturbing_Glutathione_Homeostasis/28181966\thttps://acs.figshare.com/articles/dataset/Four_Alkaloids_from_i_Alstonia_scholaris_i_with_Antitumor_Activity_via_Disturbing_Glutathione_Homeostasis/28181969\thttps://acs.figshare.com/articles/dataset/Four_Alkaloids_from_i_Alstonia_scholaris_i_with_Antitumor_Activity_via_Disturbing_Glutathione_Homeostasis/28181978\thttps://acs.figshare.com/articles/dataset/Four_Alkaloids_from_i_Alstonia_scholaris_i_with_Antitumor_Activity_via_Disturbing_Glutathione_Homeostasis/28181990 | Y12: =IF(U12<>U13,$Y$1&" --pubDOI "& U12&" --dataDOI """&SUBSTITUTE(U12&X12&"""","https://doi.org/",""),"") | Z12: ="<br><a href="""&Q12&""">"&Q12&"</a>" -> <br><a href="https://doi.org/10.1021/acs.joc.4c02450.s006">https://doi.org/10.1021/acs.joc.4c02450.s006</a> | AA12: =IF(AB12="","",MID(AB12,1,LEN(AB12)-4)&".zip") -> jo5c00955_si_002.zip | AB12: jo5c00955_si_002.xyz
A13: 12 | B13: =V13 -> jo4c02450 | C13: =IF(Y13="","",IF(OR(O13,F13=1,M13=""),"#"&B13 &" "&G13,B13&IF(G13="",""," # " &G13))) | D13: =IF(F13=1,"",IF(AND(D12="",S12=S13),"",S13-SUM(F$2:F12))) -> 5 | E13: =IF(B13=B12,"1","0") -> 1 | F13: 0 | M13: =IF(OR(O13,D13=""),"","/*"&D13&" " & B13 &" */"""&Q13&""",//"&T13) -> /*5 jo4c02450 */"https://doi.org/10.1021/acs.joc.4c02450.s007",//Four Alkaloids from Alstonia scholaris with Antitumor Activity via Disturbing Glutathione Homeostasis | N13: =VLOOKUP(W13,AA:AB,2,FALSE) -> #N/A | O13: =NOT(ISNA(VLOOKUP(W13,AA:AA,1,FALSE))) -> FALSE | P13: https://acs.figshare.com/articles/dataset/Four_Alkaloids_from_i_Alstonia_scholaris_i_with_Antitumor_Activity_via_Disturbing_Glutathione_Homeostasis/28181993 | Q13: https://doi.org/10.1021/acs.joc.4c02450.s007 | R13: =MID(Q13,LEN(Q13)-2,4) -> 007 | S13: =IF(U13=U12,S12,S12+1) -> 5 | T13: =VLOOKUP(Q13,original!B:C,2,FALSE) -> Four Alkaloids from Alstonia scholaris with Antitumor Activity via Disturbing Glutathione Homeostasis | U13: https://doi.org/10.1021/acs.joc.4c02450 | V13: =SUBSTITUTE(SUBSTITUTE(MID(U13,LEN(U13)-8,100),"c.","jo"),"t.","ol") -> jo4c02450 | W13: =B13&"_si_"&R13&".zip" -> jo4c02450_si_007.zip | X13: =IF(U13<>U12,P13,X12&"\t"&P13) -> https://acs.figshare.com/articles/dataset/Four_Alkaloids_from_i_Alstonia_scholaris_i_with_Antitumor_Activity_via_Disturbing_Glutathione_Homeostasis/28181963\thttps://acs.figshare.com/articles/dataset/Four_Alkaloids_from_i_Alstonia_scholaris_i_with_Antitumor_Activity_via_Disturbing_Glutathione_Homeostasis/28181966\thttps://acs.figshare.com/articles/dataset/Four_Alkaloids_from_i_Alstonia_scholaris_i_with_Antitumor_Activity_via_Disturbing_Glutathione_Homeostasis/28181969\thttps://acs.figshare.com/articles/dataset/Four_Alkaloids_from_i_Alstonia_scholaris_i_with_Antitumor_Activity_via_Disturbing_Glutathione_Homeostasis/28181978\thttps://acs.figshare.com/articles/dataset/Four_Alkaloids_from_i_Alstonia_scholaris_i_with_Antitumor_Activity_via_Disturbing_Glutathione_Homeostasis/28181990\thttps://acs.figshare.com/articles/dataset/Four_Alkaloids_from_i_Alstonia_scholaris_i_with_Antitumor_Activity_via_Disturbing_Glutathione_Homeostasis/28181993 | Y13: =IF(U13<>U14,$Y$1&" --pubDOI "& U13&" --dataDOI """&SUBSTITUTE(U13&X13&"""","https://doi.org/",""),"") | Z13: ="<br><a href="""&Q13&""">"&Q13&"</a>" -> <br><a href="https://doi.org/10.1021/acs.joc.4c02450.s007">https://doi.org/10.1021/acs.joc.4c02450.s007</a> | AA13: =IF(AB13="","",MID(AB13,1,LEN(AB13)-4)&".zip") -> jo5c01112_si_002.zip | AB13: jo5c01112_si_002.xyz
A14: 13 | B14: =V14 -> jo4c02450 | C14: =IF(Y14="","",IF(OR(O14,F14=1,M14=""),"#"&B14 &" "&G14,B14&IF(G14="",""," # " &G14))) | D14: =IF(F14=1,"",IF(AND(D13="",S13=S14),"",S14-SUM(F$2:F13))) -> 5 | E14: =IF(B14=B13,"1","0") -> 1 | F14: 0 | M14: =IF(OR(O14,D14=""),"","/*"&D14&" " & B14 &" */"""&Q14&""",//"&T14) -> /*5 jo4c02450 */"https://doi.org/10.1021/acs.joc.4c02450.s008",//Four Alkaloids from Alstonia scholaris with Antitumor Activity via Disturbing Glutathione Homeostasis | N14: =VLOOKUP(W14,AA:AB,2,FALSE) -> #N/A | O14: =NOT(ISNA(VLOOKUP(W14,AA:AA,1,FALSE))) -> FALSE | P14: https://acs.figshare.com/articles/dataset/Four_Alkaloids_from_i_Alstonia_scholaris_i_with_Antitumor_Activity_via_Disturbing_Glutathione_Homeostasis/28181996 | Q14: https://doi.org/10.1021/acs.joc.4c02450.s008 | R14: =MID(Q14,LEN(Q14)-2,4) -> 008 | S14: =IF(U14=U13,S13,S13+1) -> 5 | T14: =VLOOKUP(Q14,original!B:C,2,FALSE) -> Four Alkaloids from Alstonia scholaris with Antitumor Activity via Disturbing Glutathione Homeostasis | U14: https://doi.org/10.1021/acs.joc.4c02450 | V14: =SUBSTITUTE(SUBSTITUTE(MID(U14,LEN(U14)-8,100),"c.","jo"),"t.","ol") -> jo4c02450 | W14: =B14&"_si_"&R14&".zip" -> jo4c02450_si_008.zip | X14: =IF(U14<>U13,P14,X13&"\t"&P14) -> https://acs.figshare.com/articles/dataset/Four_Alkaloids_from_i_Alstonia_scholaris_i_with_Antitumor_Activity_via_Disturbing_Glutathione_Homeostasis/28181963\thttps://acs.figshare.com/articles/dataset/Four_Alkaloids_from_i_Alstonia_scholaris_i_with_Antitumor_Activity_via_Disturbing_Glutathione_Homeostasis/28181966\thttps://acs.figshare.com/articles/dataset/Four_Alkaloids_from_i_Alstonia_scholaris_i_with_Antitumor_Activity_via_Disturbing_Glutathione_Homeostasis/28181969\thttps://acs.figshare.com/articles/dataset/Four_Alkaloids_from_i_Alstonia_scholaris_i_with_Antitumor_Activity_via_Disturbing_Glutathione_Homeostasis/28181978\thttps://acs.figshare.com/articles/dataset/Four_Alkaloids_from_i_Alstonia_scholaris_i_with_Antitumor_Activity_via_Disturbing_Glutathione_Homeostasis/28181990\thttps://acs.figshare.com/articles/dataset/Four_Alkaloids_from_i_Alstonia_scholaris_i_with_Antitumor_Activity_via_Disturbing_Glutathione_Homeostasis/28181993\thttps://acs.figshare.com/articles/dataset/Four_Alkaloids_from_i_Alstonia_scholaris_i_with_Antitumor_Activity_via_Disturbing_Glutathione_Homeostasis/28181996 | Y14: =IF(U14<>U15,$Y$1&" --pubDOI "& U14&" --dataDOI """&SUBSTITUTE(U14&X14&"""","https://doi.org/",""),"") | Z14: ="<br><a href="""&Q14&""">"&Q14&"</a>" -> <br><a href="https://doi.org/10.1021/acs.joc.4c02450.s008">https://doi.org/10.1021/acs.joc.4c02450.s008</a> | AA14: =IF(AB14="","",MID(AB14,1,LEN(AB14)-4)&".zip") -> jo5c01225_si_001.zip | AB14: jo5c01225_si_001.xyz
A15: 14 | B15: =V15 -> jo4c02450 | C15: =IF(Y15="","",IF(OR(O15,F15=1,M15=""),"#"&B15 &" "&G15,B15&IF(G15="",""," # " &G15))) -> jo4c02450 | D15: =IF(F15=1,"",IF(AND(D14="",S14=S15),"",S15-SUM(F$2:F14))) -> 5 | E15: =IF(B15=B14,"1","0") -> 1 | F15: 0 | H15: 8 | I15: 25 | M15: =IF(OR(O15,D15=""),"","/*"&D15&" " & B15 &" */"""&Q15&""",//"&T15) -> /*5 jo4c02450 */"https://doi.org/10.1021/acs.joc.4c02450.s009",//Four Alkaloids from Alstonia scholaris with Antitumor Activity via Disturbing Glutathione Homeostasis | N15: =VLOOKUP(W15,AA:AB,2,FALSE) -> #N/A | O15: =NOT(ISNA(VLOOKUP(W15,AA:AA,1,FALSE))) -> FALSE | P15: https://acs.figshare.com/articles/dataset/Four_Alkaloids_from_i_Alstonia_scholaris_i_with_Antitumor_Activity_via_Disturbing_Glutathione_Homeostasis/28181999 | Q15: https://doi.org/10.1021/acs.joc.4c02450.s009 | R15: =MID(Q15,LEN(Q15)-2,4) -> 009 | S15: =IF(U15=U14,S14,S14+1) -> 5 | T15: =VLOOKUP(Q15,original!B:C,2,FALSE) -> Four Alkaloids from Alstonia scholaris with Antitumor Activity via Disturbing Glutathione Homeostasis | U15: https://doi.org/10.1021/acs.joc.4c02450 | V15: =SUBSTITUTE(SUBSTITUTE(MID(U15,LEN(U15)-8,100),"c.","jo"),"t.","ol") -> jo4c02450 | W15: =B15&"_si_"&R15&".zip" -> jo4c02450_si_009.zip | X15: =IF(U15<>U14,P15,X14&"\t"&P15) -> https://acs.figshare.com/articles/dataset/Four_Alkaloids_from_i_Alstonia_scholaris_i_with_Antitumor_Activity_via_Disturbing_Glutathione_Homeostasis/28181963\thttps://acs.figshare.com/articles/dataset/Four_Alkaloids_from_i_Alstonia_scholaris_i_with_Antitumor_Activity_via_Disturbing_Glutathione_Homeostasis/28181966\thttps://acs.figshare.com/articles/dataset/Four_Alkaloids_from_i_Alstonia_scholaris_i_with_Antitumor_Activity_via_Disturbing_Glutathione_Homeostasis/28181969\thttps://acs.figshare.com/articles/dataset/Four_Alkaloids_from_i_Alstonia_scholaris_i_with_Antitumor_Activity_via_Disturbing_Glutathione_Homeostasis/28181978\thttps://acs.figshare.com/articles/dataset/Four_Alkaloids_from_i_Alstonia_scholaris_i_with_Antitumor_Activity_via_Disturbing_Glutathione_Homeostasis/28181990\thttps://acs.figshare.com/articles/dataset/Four_Alkaloids_from_i_Alstonia_scholaris_i_with_Antitumor_Activity_via_Disturbing_Glutathione_Homeostasis/28181993\thttps://acs.figshare.com/articles/dataset/Four_Alkaloids_from_i_Alstonia_scholaris_i_with_Antitumor_Activity_via_Disturbing_Glutathione_Homeostasis/28181996\thttps://acs.figshare.com/articles/dataset/Four_Alkaloids_from_i_Alstonia_scholaris_i_with_Antitumor_Activity_via_Disturbing_Glutathione_Homeostasis/28181999 | Y15: =IF(U15<>U16,$Y$1&" --pubDOI "& U15&" --dataDOI """&SUBSTITUTE(U15&X15&"""","https://doi.org/",""),"") -> --localSource c:/temp/acs2/data --targetDir c:/temp/acs2/$DOI$ --noDownload --readOnly --pubDOI https://doi.org/10.1021/acs.joc.4c02450 --dataDOI "10.1021/acs.joc.4c02450https://acs.figshare.com/articles/dataset/Four_Alkaloids_from_i_Alstonia_scholaris_i_with_Antitumor_Activity_via_Disturbing_Glutathione_Homeostasis/28181963\thttps://acs.figshare.com/articles/dataset/Four_Alkaloids_from_i_Alstonia_scholaris_i_with_Antitumor_Activity_via_Disturbing_Glutathione_Homeostasis/28181966\thttps://acs.figshare.com/articles/dataset/Four_Alkaloids_from_i_Alstonia_scholaris_i_with_Antitumor_Activity_via_Disturbing_Glutathione_Homeostasis/28181969\thttps://acs.figshare.com/articles/dataset/Four_Alkaloids_from_i_Alstonia_scholaris_i_with_Antitumor_Activity_via_Disturbing_Glutathione_Homeostasis/28181978\thttps://acs.figshare.com/articles/dataset/Four_Alkaloids_from_i_Alstonia_scholaris_i_with_Antitumor_Activity_via_Disturbing_Glutathione_Homeostasis/28181990\thttps://acs.figshare.com/articles/dataset/Four_Alkaloids_from_i_Alstonia_scholaris_i_with_Antitumor_Activity_via_Disturbing_Glutathione_Homeostasis/28181993\thttps://acs.figshare.com/articles/dataset/Four_Alkaloids_from_i_Alstonia_scholaris_i_with_Antitumor_Activity_via_Disturbing_Glutathione_Homeostasis/28181996\thttps://acs.figshare.com/articles/dataset/Four_Alkaloids_from_i_Alstonia_scholaris_i_with_Antitumor_Activity_via_Disturbing_Glutathione_Homeostasis/28181999" | Z15: ="<br><a href="""&Q15&""">"&Q15&"</a>" -> <br><a href="https://doi.org/10.1021/acs.joc.4c02450.s009">https://doi.org/10.1021/acs.joc.4c02450.s009</a> | AA15: =IF(AB15="","",MID(AB15,1,LEN(AB15)-4)&".zip") -> jo5c01560_si_003.zip | AB15: jo5c01560_si_003.xyz
A16: 15 | B16: =V16 -> jo4c02490 | C16: =IF(Y16="","",IF(OR(O16,F16=1,M16=""),"#"&B16 &" "&G16,B16&IF(G16="",""," # " &G16))) -> jo4c02490 | D16: =IF(F16=1,"",IF(AND(D15="",S15=S16),"",S16-SUM(F$2:F15))) -> 6 | E16: =IF(B16=B15,"1","0") -> 0 | F16: 0 | H16: 48 | I16: 107 | M16: =IF(OR(O16,D16=""),"","/*"&D16&" " & B16 &" */"""&Q16&""",//"&T16) -> /*6 jo4c02490 */"https://doi.org/10.1021/acs.joc.4c02490.s002",//CO2•– Enabled Synthesis of Phenanthridinones, Oxindoles, Isoindolinones, and Spirolactams | N16: =VLOOKUP(W16,AA:AB,2,FALSE) -> #N/A | O16: =NOT(ISNA(VLOOKUP(W16,AA:AA,1,FALSE))) -> FALSE | P16: https://acs.figshare.com/articles/dataset/CO_sub_2_sub_sup_sup_Enabled_Synthesis_of_Phenanthridinones_Oxindoles_Isoindolinones_and_Spirolactams/28516677 | Q16: https://doi.org/10.1021/acs.joc.4c02490.s002 | R16: =MID(Q16,LEN(Q16)-2,4) -> 002 | S16: =IF(U16=U15,S15,S15+1) -> 6 | T16: =VLOOKUP(Q16,original!B:C,2,FALSE) -> CO2•– Enabled Synthesis of Phenanthridinones, Oxindoles, Isoindolinones, and Spirolactams | U16: https://doi.org/10.1021/acs.joc.4c02490 | V16: =SUBSTITUTE(SUBSTITUTE(MID(U16,LEN(U16)-8,100),"c.","jo"),"t.","ol") -> jo4c02490 | W16: =B16&"_si_"&R16&".zip" -> jo4c02490_si_002.zip | X16: =IF(U16<>U15,P16,X15&"\t"&P16) -> https://acs.figshare.com/articles/dataset/CO_sub_2_sub_sup_sup_Enabled_Synthesis_of_Phenanthridinones_Oxindoles_Isoindolinones_and_Spirolactams/28516677 | Y16: =IF(U16<>U17,$Y$1&" --pubDOI "& U16&" --dataDOI """&SUBSTITUTE(U16&X16&"""","https://doi.org/",""),"") -> --localSource c:/temp/acs2/data --targetDir c:/temp/acs2/$DOI$ --noDownload --readOnly --pubDOI https://doi.org/10.1021/acs.joc.4c02490 --dataDOI "10.1021/acs.joc.4c02490https://acs.figshare.com/articles/dataset/CO_sub_2_sub_sup_sup_Enabled_Synthesis_of_Phenanthridinones_Oxindoles_Isoindolinones_and_Spirolactams/28516677" | Z16: ="<br><a href="""&Q16&""">"&Q16&"</a>" -> <br><a href="https://doi.org/10.1021/acs.joc.4c02490.s002">https://doi.org/10.1021/acs.joc.4c02490.s002</a> | AA16: =IF(AB16="","",MID(AB16,1,LEN(AB16)-4)&".zip") -> jo5c01560_si_007.zip | AB16: jo5c01560_si_007.xyz
A17: 16 | B17: =V17 -> jo4c02546 | C17: =IF(Y17="","",IF(OR(O17,F17=1,M17=""),"#"&B17 &" "&G17,B17&IF(G17="",""," # " &G17))) -> #jo4c02546 CALCULATION ONLY XYZ | D17: =IF(F17=1,"",IF(AND(D16="",S16=S17),"",S17-SUM(F$2:F16))) | E17: =IF(B17=B16,"1","0") -> 0 | F17: 1 | G17: CALCULATION ONLY XYZ | M17: =IF(OR(O17,D17=""),"","/*"&D17&" " & B17 &" */"""&Q17&""",//"&T17) | N17: =VLOOKUP(W17,AA:AB,2,FALSE) -> #N/A | O17: =NOT(ISNA(VLOOKUP(W17,AA:AA,1,FALSE))) -> FALSE | P17: https://acs.figshare.com/articles/dataset/Synergy-Promoted_Specific_Alkyltriphenylphosphonium_Binding_to_CB_8_/28379677 | Q17: https://doi.org/10.1021/acs.joc.4c02546.s002 | R17: =MID(Q17,LEN(Q17)-2,4) -> 002 | S17: =IF(U17=U16,S16,S16+1) -> 7 | T17: =VLOOKUP(Q17,original!B:C,2,FALSE) -> Synergy-Promoted Specific Alkyltriphenylphosphonium Binding to CB[8] | U17: https://doi.org/10.1021/acs.joc.4c02546 | V17: =SUBSTITUTE(SUBSTITUTE(MID(U17,LEN(U17)-8,100),"c.","jo"),"t.","ol") -> jo4c02546 | W17: =B17&"_si_"&R17&".zip" -> jo4c02546_si_002.zip | X17: =IF(U17<>U16,P17,X16&"\t"&P17) -> https://acs.figshare.com/articles/dataset/Synergy-Promoted_Specific_Alkyltriphenylphosphonium_Binding_to_CB_8_/28379677 | Y17: =IF(U17<>U18,$Y$1&" --pubDOI "& U17&" --dataDOI """&SUBSTITUTE(U17&X17&"""","https://doi.org/",""),"") -> --localSource c:/temp/acs2/data --targetDir c:/temp/acs2/$DOI$ --noDownload --readOnly --pubDOI https://doi.org/10.1021/acs.joc.4c02546 --dataDOI "10.1021/acs.joc.4c02546https://acs.figshare.com/articles/dataset/Synergy-Promoted_Specific_Alkyltriphenylphosphonium_Binding_to_CB_8_/28379677" | Z17: ="<br><a href="""&Q17&""">"&Q17&"</a>" -> <br><a href="https://doi.org/10.1021/acs.joc.4c02546.s002">https://doi.org/10.1021/acs.joc.4c02546.s002</a> | AA17: =IF(AB17="","",MID(AB17,1,LEN(AB17)-4)&".zip") -> jo5c01560_si_010.zip | AB17: jo5c01560_si_010.xyz
A18: 17 | B18: =V18 -> jo4c02574 | C18: =IF(Y18="","",IF(OR(O18,F18=1,M18=""),"#"&B18 &" "&G18,B18&IF(G18="",""," # " &G18))) -> #jo4c02574 XLS | D18: =IF(F18=1,"",IF(AND(D17="",S17=S18),"",S18-SUM(F$2:F17))) | E18: =IF(B18=B17,"1","0") -> 0 | F18: 1 | G18: XLS | M18: =IF(OR(O18,D18=""),"","/*"&D18&" " & B18 &" */"""&Q18&""",//"&T18) | N18: =VLOOKUP(W18,AA:AB,2,FALSE) -> jo4c02574_si_002.xls | O18: =NOT(ISNA(VLOOKUP(W18,AA:AA,1,FALSE))) -> TRUE | P18: https://acs.figshare.com/articles/dataset/C_H_Aminoalkylation_of_5_Membered_Heterocycles_Influence_of_Descriptors_Data_Set_Size_and_Data_Quality_on_the_Predictiveness_of_Machine_Learning_Models_and_Expansion_of_the_Substrate_Space_Beyond_1_3-Azoles/28395051 | Q18: https://doi.org/10.1021/acs.joc.4c02574.s002 | R18: =MID(Q18,LEN(Q18)-2,4) -> 002 | S18: =IF(U18=U17,S17,S17+1) -> 8 | T18: =VLOOKUP(Q18,original!B:C,2,FALSE) -> C–H Aminoalkylation of 5‑Membered Heterocycles: Influence of Descriptors, Data Set Size, and Data Quality on the Predictiveness of Machine Learning Models and Expansion of the Substrate Space Beyond 1,3-Azoles | U18: https://doi.org/10.1021/acs.joc.4c02574 | V18: =SUBSTITUTE(SUBSTITUTE(MID(U18,LEN(U18)-8,100),"c.","jo"),"t.","ol") -> jo4c02574 | W18: =B18&"_si_"&R18&".zip" -> jo4c02574_si_002.zip | X18: =IF(U18<>U17,P18,X17&"\t"&P18) -> https://acs.figshare.com/articles/dataset/C_H_Aminoalkylation_of_5_Membered_Heterocycles_Influence_of_Descriptors_Data_Set_Size_and_Data_Quality_on_the_Predictiveness_of_Machine_Learning_Models_and_Expansion_of_the_Substrate_Space_Beyond_1_3-Azoles/28395051 | Y18: =IF(U18<>U19,$Y$1&" --pubDOI "& U18&" --dataDOI """&SUBSTITUTE(U18&X18&"""","https://doi.org/",""),"") -> --localSource c:/temp/acs2/data --targetDir c:/temp/acs2/$DOI$ --noDownload --readOnly --pubDOI https://doi.org/10.1021/acs.joc.4c02574 --dataDOI "10.1021/acs.joc.4c02574https://acs.figshare.com/articles/dataset/C_H_Aminoalkylation_of_5_Membered_Heterocycles_Influence_of_Descriptors_Data_Set_Size_and_Data_Quality_on_the_Predictiveness_of_Machine_Learning_Models_and_Expansion_of_the_Substrate_Space_Beyond_1_3-Azoles/28395051" | Z18: ="<br><a href="""&Q18&""">"&Q18&"</a>" -> <br><a href="https://doi.org/10.1021/acs.joc.4c02574.s002">https://doi.org/10.1021/acs.joc.4c02574.s002</a> | AA18: =IF(AB18="","",MID(AB18,1,LEN(AB18)-4)&".zip") -> jo5c01560_si_012.zip | AB18: jo5c01560_si_012.xyz
A19: 18 | B19: =V19 -> jo4c02600 | C19: =IF(Y19="","",IF(OR(O19,F19=1,M19=""),"#"&B19 &" "&G19,B19&IF(G19="",""," # " &G19))) -> jo4c02600 | D19: =IF(F19=1,"",IF(AND(D18="",S18=S19),"",S19-SUM(F$2:F18))) -> 7 | E19: =IF(B19=B18,"1","0") -> 0 | F19: 0 | H19: 33 | I19: 71 | M19: =IF(OR(O19,D19=""),"","/*"&D19&" " & B19 &" */"""&Q19&""",//"&T19) -> /*7 jo4c02600 */"https://doi.org/10.1021/acs.joc.4c02600.s002",//Visible-Light-Mediated Three-Component Alkene 1,2-Alkylpyridylation Reaction Using Alkylboronic Acids as Radical Precursors for the Synthesis of 4‑Alkylpyridines | N19: =VLOOKUP(W19,AA:AB,2,FALSE) -> #N/A | O19: =NOT(ISNA(VLOOKUP(W19,AA:AA,1,FALSE))) -> FALSE | P19: https://acs.figshare.com/articles/dataset/Visible-Light-Mediated_Three-Component_Alkene_1_2-Alkylpyridylation_Reaction_Using_Alkylboronic_Acids_as_Radical_Precursors_for_the_Synthesis_of_4_Alkylpyridines/28524997 | Q19: https://doi.org/10.1021/acs.joc.4c02600.s002 | R19: =MID(Q19,LEN(Q19)-2,4) -> 002 | S19: =IF(U19=U18,S18,S18+1) -> 9 | T19: =VLOOKUP(Q19,original!B:C,2,FALSE) -> Visible-Light-Mediated Three-Component Alkene 1,2-Alkylpyridylation Reaction Using Alkylboronic Acids as Radical Precursors for the Synthesis of 4‑Alkylpyridines | U19: https://doi.org/10.1021/acs.joc.4c02600 | V19: =SUBSTITUTE(SUBSTITUTE(MID(U19,LEN(U19)-8,100),"c.","jo"),"t.","ol") -> jo4c02600 | W19: =B19&"_si_"&R19&".zip" -> jo4c02600_si_002.zip | X19: =IF(U19<>U18,P19,X18&"\t"&P19) -> https://acs.figshare.com/articles/dataset/Visible-Light-Mediated_Three-Component_Alkene_1_2-Alkylpyridylation_Reaction_Using_Alkylboronic_Acids_as_Radical_Precursors_for_the_Synthesis_of_4_Alkylpyridines/28524997 | Y19: =IF(U19<>U20,$Y$1&" --pubDOI "& U19&" --dataDOI """&SUBSTITUTE(U19&X19&"""","https://doi.org/",""),"") -> --localSource c:/temp/acs2/data --targetDir c:/temp/acs2/$DOI$ --noDownload --readOnly --pubDOI https://doi.org/10.1021/acs.joc.4c02600 --dataDOI "10.1021/acs.joc.4c02600https://acs.figshare.com/articles/dataset/Visible-Light-Mediated_Three-Component_Alkene_1_2-Alkylpyridylation_Reaction_Using_Alkylboronic_Acids_as_Radical_Precursors_for_the_Synthesis_of_4_Alkylpyridines/28524997" | Z19: ="<br><a href="""&Q19&""">"&Q19&"</a>" -> <br><a href="https://doi.org/10.1021/acs.joc.4c02600.s002">https://doi.org/10.1021/acs.joc.4c02600.s002</a> | AA19: =IF(AB19="","",MID(AB19,1,LEN(AB19)-4)&".zip") -> jo5c01560_si_005.zip | AB19: jo5c01560_si_005.xyz
A20: 19 | B20: =V20 -> jo4c02622 | C20: =IF(Y20="","",IF(OR(O20,F20=1,M20=""),"#"&B20 &" "&G20,B20&IF(G20="",""," # " &G20))) | D20: =IF(F20=1,"",IF(AND(D19="",S19=S20),"",S20-SUM(F$2:F19))) -> 8 | E20: =IF(B20=B19,"1","0") -> 0 | F20: 0 | M20: =IF(OR(O20,D20=""),"","/*"&D20&" " & B20 &" */"""&Q20&""",//"&T20) -> /*8 jo4c02622 */"https://doi.org/10.1021/acs.joc.4c02622.s001",//Direct Synthesis of 2‑Functionalized 3‑Nitroindoles from Diazo(nitro)acetanilides | N20: =VLOOKUP(W20,AA:AB,2,FALSE) -> #N/A | O20: =NOT(ISNA(VLOOKUP(W20,AA:AA,1,FALSE))) -> FALSE | P20: https://acs.figshare.com/articles/dataset/Direct_Synthesis_of_2_Functionalized_3_Nitroindoles_from_Diazo_nitro_acetanilides/28156320 | Q20: https://doi.org/10.1021/acs.joc.4c02622.s001 | R20: =MID(Q20,LEN(Q20)-2,4) -> 001 | S20: =IF(U20=U19,S19,S19+1) -> 10 | T20: =VLOOKUP(Q20,original!B:C,2,FALSE) -> Direct Synthesis of 2‑Functionalized 3‑Nitroindoles from Diazo(nitro)acetanilides | U20: https://doi.org/10.1021/acs.joc.4c02622 | V20: =SUBSTITUTE(SUBSTITUTE(MID(U20,LEN(U20)-8,100),"c.","jo"),"t.","ol") -> jo4c02622 | W20: =B20&"_si_"&R20&".zip" -> jo4c02622_si_001.zip | X20: =IF(U20<>U19,P20,X19&"\t"&P20) -> https://acs.figshare.com/articles/dataset/Direct_Synthesis_of_2_Functionalized_3_Nitroindoles_from_Diazo_nitro_acetanilides/28156320 | Y20: =IF(U20<>U21,$Y$1&" --pubDOI "& U20&" --dataDOI """&SUBSTITUTE(U20&X20&"""","https://doi.org/",""),"") | Z20: ="<br><a href="""&Q20&""">"&Q20&"</a>" -> <br><a href="https://doi.org/10.1021/acs.joc.4c02622.s001">https://doi.org/10.1021/acs.joc.4c02622.s001</a> | AA20: =IF(AB20="","",MID(AB20,1,LEN(AB20)-4)&".zip") -> jo5c01774_si_002.zip | AB20: jo5c01774_si_002.xyz
A21: 20 | B21: =V21 -> jo4c02622 | C21: =IF(Y21="","",IF(OR(O21,F21=1,M21=""),"#"&B21 &" "&G21,B21&IF(G21="",""," # " &G21))) | D21: =IF(F21=1,"",IF(AND(D20="",S20=S21),"",S21-SUM(F$2:F20))) -> 8 | E21: =IF(B21=B20,"1","0") -> 1 | F21: 0 | M21: =IF(OR(O21,D21=""),"","/*"&D21&" " & B21 &" */"""&Q21&""",//"&T21) -> /*8 jo4c02622 */"https://doi.org/10.1021/acs.joc.4c02622.s002",//Direct Synthesis of 2‑Functionalized 3‑Nitroindoles from Diazo(nitro)acetanilides | N21: =VLOOKUP(W21,AA:AB,2,FALSE) -> #N/A | O21: =NOT(ISNA(VLOOKUP(W21,AA:AA,1,FALSE))) -> FALSE | P21: https://acs.figshare.com/articles/dataset/Direct_Synthesis_of_2_Functionalized_3_Nitroindoles_from_Diazo_nitro_acetanilides/28156323 | Q21: https://doi.org/10.1021/acs.joc.4c02622.s002 | R21: =MID(Q21,LEN(Q21)-2,4) -> 002 | S21: =IF(U21=U20,S20,S20+1) -> 10 | T21: =VLOOKUP(Q21,original!B:C,2,FALSE) -> Direct Synthesis of 2‑Functionalized 3‑Nitroindoles from Diazo(nitro)acetanilides | U21: https://doi.org/10.1021/acs.joc.4c02622 | V21: =SUBSTITUTE(SUBSTITUTE(MID(U21,LEN(U21)-8,100),"c.","jo"),"t.","ol") -> jo4c02622 | W21: =B21&"_si_"&R21&".zip" -> jo4c02622_si_002.zip | X21: =IF(U21<>U20,P21,X20&"\t"&P21) -> https://acs.figshare.com/articles/dataset/Direct_Synthesis_of_2_Functionalized_3_Nitroindoles_from_Diazo_nitro_acetanilides/28156320\thttps://acs.figshare.com/articles/dataset/Direct_Synthesis_of_2_Functionalized_3_Nitroindoles_from_Diazo_nitro_acetanilides/28156323 | Y21: =IF(U21<>U22,$Y$1&" --pubDOI "& U21&" --dataDOI """&SUBSTITUTE(U21&X21&"""","https://doi.org/",""),"") | Z21: ="<br><a href="""&Q21&""">"&Q21&"</a>" -> <br><a href="https://doi.org/10.1021/acs.joc.4c02622.s002">https://doi.org/10.1021/acs.joc.4c02622.s002</a> | AA21: =IF(AB21="","",MID(AB21,1,LEN(AB21)-4)&".zip") -> jo5c01560_si_004.zip | AB21: jo5c01560_si_004.xyz
A22: 21 | B22: =V22 -> jo4c02622 | C22: =IF(Y22="","",IF(OR(O22,F22=1,M22=""),"#"&B22 &" "&G22,B22&IF(G22="",""," # " &G22))) -> jo4c02622 | D22: =IF(F22=1,"",IF(AND(D21="",S21=S22),"",S22-SUM(F$2:F21))) -> 8 | E22: =IF(B22=B21,"1","0") -> 1 | F22: 0 | H22: 65 | I22: 154 | J22: 65 | M22: =IF(OR(O22,D22=""),"","/*"&D22&" " & B22 &" */"""&Q22&""",//"&T22) -> /*8 jo4c02622 */"https://doi.org/10.1021/acs.joc.4c02622.s004",//Direct Synthesis of 2‑Functionalized 3‑Nitroindoles from Diazo(nitro)acetanilides | N22: =VLOOKUP(W22,AA:AB,2,FALSE) -> #N/A | O22: =NOT(ISNA(VLOOKUP(W22,AA:AA,1,FALSE))) -> FALSE | P22: https://acs.figshare.com/articles/dataset/Direct_Synthesis_of_2_Functionalized_3_Nitroindoles_from_Diazo_nitro_acetanilides/28156329 | Q22: https://doi.org/10.1021/acs.joc.4c02622.s004 | R22: =MID(Q22,LEN(Q22)-2,4) -> 004 | S22: =IF(U22=U21,S21,S21+1) -> 10 | T22: =VLOOKUP(Q22,original!B:C,2,FALSE) -> Direct Synthesis of 2‑Functionalized 3‑Nitroindoles from Diazo(nitro)acetanilides | U22: https://doi.org/10.1021/acs.joc.4c02622 | V22: =SUBSTITUTE(SUBSTITUTE(MID(U22,LEN(U22)-8,100),"c.","jo"),"t.","ol") -> jo4c02622 | W22: =B22&"_si_"&R22&".zip" -> jo4c02622_si_004.zip | X22: =IF(U22<>U21,P22,X21&"\t"&P22) -> https://acs.figshare.com/articles/dataset/Direct_Synthesis_of_2_Functionalized_3_Nitroindoles_from_Diazo_nitro_acetanilides/28156320\thttps://acs.figshare.com/articles/dataset/Direct_Synthesis_of_2_Functionalized_3_Nitroindoles_from_Diazo_nitro_acetanilides/28156323\thttps://acs.figshare.com/articles/dataset/Direct_Synthesis_of_2_Functionalized_3_Nitroindoles_from_Diazo_nitro_acetanilides/28156329 | Y22: =IF(U22<>U23,$Y$1&" --pubDOI "& U22&" --dataDOI """&SUBSTITUTE(U22&X22&"""","https://doi.org/",""),"") -> --localSource c:/temp/acs2/data --targetDir c:/temp/acs2/$DOI$ --noDownload --readOnly --pubDOI https://doi.org/10.1021/acs.joc.4c02622 --dataDOI "10.1021/acs.joc.4c02622https://acs.figshare.com/articles/dataset/Direct_Synthesis_of_2_Functionalized_3_Nitroindoles_from_Diazo_nitro_acetanilides/28156320\thttps://acs.figshare.com/articles/dataset/Direct_Synthesis_of_2_Functionalized_3_Nitroindoles_from_Diazo_nitro_acetanilides/28156323\thttps://acs.figshare.com/articles/dataset/Direct_Synthesis_of_2_Functionalized_3_Nitroindoles_from_Diazo_nitro_acetanilides/28156329" | Z22: ="<br><a href="""&Q22&""">"&Q22&"</a>" -> <br><a href="https://doi.org/10.1021/acs.joc.4c02622.s004">https://doi.org/10.1021/acs.joc.4c02622.s004</a> | AA22: =IF(AB22="","",MID(AB22,1,LEN(AB22)-4)&".zip") -> jo5c01560_si_011.zip | AB22: jo5c01560_si_011.xyz
A23: 22 | B23: =V23 -> jo4c02634 | C23: =IF(Y23="","",IF(OR(O23,F23=1,M23=""),"#"&B23 &" "&G23,B23&IF(G23="",""," # " &G23))) -> jo4c02634 | D23: =IF(F23=1,"",IF(AND(D22="",S22=S23),"",S23-SUM(F$2:F22))) -> 9 | E23: =IF(B23=B22,"1","0") -> 0 | F23: 0 | H23: 24 | I23: 47 | M23: =IF(OR(O23,D23=""),"","/*"&D23&" " & B23 &" */"""&Q23&""",//"&T23) -> /*9 jo4c02634 */"https://doi.org/10.1021/acs.joc.4c02634.s002",//Synthesis of N‑Heterocycle-Ligated Porphyrins Using Iodobenzene Diacetate Enabled Regioselective Cross-Dehydrogenation of Porphyrins and NH-Heteroaromatics | N23: =VLOOKUP(W23,AA:AB,2,FALSE) -> #N/A | O23: =NOT(ISNA(VLOOKUP(W23,AA:AA,1,FALSE))) -> FALSE | P23: https://acs.figshare.com/articles/dataset/Synthesis_of_N_Heterocycle-Ligated_Porphyrins_Using_Iodobenzene_Diacetate_Enabled_Regioselective_Cross-Dehydrogenation_of_Porphyrins_and_NH-Heteroaromatics/28519682 | Q23: https://doi.org/10.1021/acs.joc.4c02634.s002 | R23: =MID(Q23,LEN(Q23)-2,4) -> 002 | S23: =IF(U23=U22,S22,S22+1) -> 11 | T23: =VLOOKUP(Q23,original!B:C,2,FALSE) -> Synthesis of N‑Heterocycle-Ligated Porphyrins Using Iodobenzene Diacetate Enabled Regioselective Cross-Dehydrogenation of Porphyrins and NH-Heteroaromatics | U23: https://doi.org/10.1021/acs.joc.4c02634 | V23: =SUBSTITUTE(SUBSTITUTE(MID(U23,LEN(U23)-8,100),"c.","jo"),"t.","ol") -> jo4c02634 | W23: =B23&"_si_"&R23&".zip" -> jo4c02634_si_002.zip | X23: =IF(U23<>U22,P23,X22&"\t"&P23) -> https://acs.figshare.com/articles/dataset/Synthesis_of_N_Heterocycle-Ligated_Porphyrins_Using_Iodobenzene_Diacetate_Enabled_Regioselective_Cross-Dehydrogenation_of_Porphyrins_and_NH-Heteroaromatics/28519682 | Y23: =IF(U23<>U24,$Y$1&" --pubDOI "& U23&" --dataDOI """&SUBSTITUTE(U23&X23&"""","https://doi.org/",""),"") -> --localSource c:/temp/acs2/data --targetDir c:/temp/acs2/$DOI$ --noDownload --readOnly --pubDOI https://doi.org/10.1021/acs.joc.4c02634 --dataDOI "10.1021/acs.joc.4c02634https://acs.figshare.com/articles/dataset/Synthesis_of_N_Heterocycle-Ligated_Porphyrins_Using_Iodobenzene_Diacetate_Enabled_Regioselective_Cross-Dehydrogenation_of_Porphyrins_and_NH-Heteroaromatics/28519682" | Z23: ="<br><a href="""&Q23&""">"&Q23&"</a>" -> <br><a href="https://doi.org/10.1021/acs.joc.4c02634.s002">https://doi.org/10.1021/acs.joc.4c02634.s002</a> | AA23: =IF(AB23="","",MID(AB23,1,LEN(AB23)-4)&".zip") -> jo5c01560_si_008.zip | AB23: jo5c01560_si_008.xyz
A24: 23 | B24: =V24 -> jo4c02638 | C24: =IF(Y24="","",IF(OR(O24,F24=1,M24=""),"#"&B24 &" "&G24,B24&IF(G24="",""," # " &G24))) -> jo4c02638 | D24: =IF(F24=1,"",IF(AND(D23="",S23=S24),"",S24-SUM(F$2:F23))) -> 10 | E24: =IF(B24=B23,"1","0") -> 0 | F24: 0 | H24: 86 | I24: 179 | M24: =IF(OR(O24,D24=""),"","/*"&D24&" " & B24 &" */"""&Q24&""",//"&T24) -> /*10 jo4c02638 */"https://doi.org/10.1021/acs.joc.4c02638.s002",//NHC-BH3‑Mediated Reduction of Sulfonyl Hydrazides into Disulfides and Further Cross-Coupling with Chlorostibine and Bioactivities | N24: =VLOOKUP(W24,AA:AB,2,FALSE) -> #N/A | O24: =NOT(ISNA(VLOOKUP(W24,AA:AA,1,FALSE))) -> FALSE | P24: https://acs.figshare.com/articles/dataset/NHC-BH_sub_3_sub_Mediated_Reduction_of_Sulfonyl_Hydrazides_into_Disulfides_and_Further_Cross-Coupling_with_Chlorostibine_and_Bioactivities/28432991 | Q24: https://doi.org/10.1021/acs.joc.4c02638.s002 | R24: =MID(Q24,LEN(Q24)-2,4) -> 002 | S24: =IF(U24=U23,S23,S23+1) -> 12 | T24: =VLOOKUP(Q24,original!B:C,2,FALSE) -> NHC-BH3‑Mediated Reduction of Sulfonyl Hydrazides into Disulfides and Further Cross-Coupling with Chlorostibine and Bioactivities | U24: https://doi.org/10.1021/acs.joc.4c02638 | V24: =SUBSTITUTE(SUBSTITUTE(MID(U24,LEN(U24)-8,100),"c.","jo"),"t.","ol") -> jo4c02638 | W24: =B24&"_si_"&R24&".zip" -> jo4c02638_si_002.zip | X24: =IF(U24<>U23,P24,X23&"\t"&P24) -> https://acs.figshare.com/articles/dataset/NHC-BH_sub_3_sub_Mediated_Reduction_of_Sulfonyl_Hydrazides_into_Disulfides_and_Further_Cross-Coupling_with_Chlorostibine_and_Bioactivities/28432991 | Y24: =IF(U24<>U25,$Y$1&" --pubDOI "& U24&" --dataDOI """&SUBSTITUTE(U24&X24&"""","https://doi.org/",""),"") -> --localSource c:/temp/acs2/data --targetDir c:/temp/acs2/$DOI$ --noDownload --readOnly --pubDOI https://doi.org/10.1021/acs.joc.4c02638 --dataDOI "10.1021/acs.joc.4c02638https://acs.figshare.com/articles/dataset/NHC-BH_sub_3_sub_Mediated_Reduction_of_Sulfonyl_Hydrazides_into_Disulfides_and_Further_Cross-Coupling_with_Chlorostibine_and_Bioactivities/28432991" | Z24: ="<br><a href="""&Q24&""">"&Q24&"</a>" -> <br><a href="https://doi.org/10.1021/acs.joc.4c02638.s002">https://doi.org/10.1021/acs.joc.4c02638.s002</a> | AA24: =IF(AB24="","",MID(AB24,1,LEN(AB24)-4)&".zip") -> jo5c01560_si_013.zip | AB24: jo5c01560_si_013.xyz
A25: 24 | B25: =V25 -> jo4c02652 | C25: =IF(Y25="","",IF(OR(O25,F25=1,M25=""),"#"&B25 &" "&G25,B25&IF(G25="",""," # " &G25))) -> jo4c02652 | D25: =IF(F25=1,"",IF(AND(D24="",S24=S25),"",S25-SUM(F$2:F24))) -> 11 | E25: =IF(B25=B24,"1","0") -> 0 | F25: 0 | H25: 38 | I25: 141 | M25: =IF(OR(O25,D25=""),"","/*"&D25&" " & B25 &" */"""&Q25&""",//"&T25) -> /*11 jo4c02652 */"https://doi.org/10.1021/acs.joc.4c02652.s002",//Aryl Borane as a Catalyst for Dehydrative Amide Synthesis | N25: =VLOOKUP(W25,AA:AB,2,FALSE) -> #N/A | O25: =NOT(ISNA(VLOOKUP(W25,AA:AA,1,FALSE))) -> FALSE | P25: https://acs.figshare.com/articles/dataset/Aryl_Borane_as_a_Catalyst_for_Dehydrative_Amide_Synthesis/28313122 | Q25: https://doi.org/10.1021/acs.joc.4c02652.s002 | R25: =MID(Q25,LEN(Q25)-2,4) -> 002 | S25: =IF(U25=U24,S24,S24+1) -> 13 | T25: =VLOOKUP(Q25,original!B:C,2,FALSE) -> Aryl Borane as a Catalyst for Dehydrative Amide Synthesis | U25: https://doi.org/10.1021/acs.joc.4c02652 | V25: =SUBSTITUTE(SUBSTITUTE(MID(U25,LEN(U25)-8,100),"c.","jo"),"t.","ol") -> jo4c02652 | W25: =B25&"_si_"&R25&".zip" -> jo4c02652_si_002.zip | X25: =IF(U25<>U24,P25,X24&"\t"&P25) -> https://acs.figshare.com/articles/dataset/Aryl_Borane_as_a_Catalyst_for_Dehydrative_Amide_Synthesis/28313122 | Y25: =IF(U25<>U26,$Y$1&" --pubDOI "& U25&" --dataDOI """&SUBSTITUTE(U25&X25&"""","https://doi.org/",""),"") -> --localSource c:/temp/acs2/data --targetDir c:/temp/acs2/$DOI$ --noDownload --readOnly --pubDOI https://doi.org/10.1021/acs.joc.4c02652 --dataDOI "10.1021/acs.joc.4c02652https://acs.figshare.com/articles/dataset/Aryl_Borane_as_a_Catalyst_for_Dehydrative_Amide_Synthesis/28313122" | Z25: ="<br><a href="""&Q25&""">"&Q25&"</a>" -> <br><a href="https://doi.org/10.1021/acs.joc.4c02652.s002">https://doi.org/10.1021/acs.joc.4c02652.s002</a> | AA25: =IF(AB25="","",MID(AB25,1,LEN(AB25)-4)&".zip") -> jo5c02123_si_002.zip | AB25: jo5c02123_si_002.xyz
A26: 25 | B26: =V26 -> jo4c02669 | C26: =IF(Y26="","",IF(OR(O26,F26=1,M26=""),"#"&B26 &" "&G26,B26&IF(G26="",""," # " &G26))) -> jo4c02669 | D26: =IF(F26=1,"",IF(AND(D25="",S25=S26),"",S26-SUM(F$2:F25))) -> 12 | E26: =IF(B26=B25,"1","0") -> 0 | F26: 0 | H26: 7 | I26: 27 | M26: =IF(OR(O26,D26=""),"","/*"&D26&" " & B26 &" */"""&Q26&""",//"&T26) -> /*12 jo4c02669 */"https://doi.org/10.1021/acs.joc.4c02669.s001",//Controlling the Symmetry of Perylene Derivatives via Selective ortho-Borylation | N26: =VLOOKUP(W26,AA:AB,2,FALSE) -> #N/A | O26: =NOT(ISNA(VLOOKUP(W26,AA:AA,1,FALSE))) -> FALSE | P26: https://acs.figshare.com/articles/dataset/Controlling_the_Symmetry_of_Perylene_Derivatives_via_Selective_i_ortho_i_-Borylation/28504775 | Q26: https://doi.org/10.1021/acs.joc.4c02669.s001 | R26: =MID(Q26,LEN(Q26)-2,4) -> 001 | S26: =IF(U26=U25,S25,S25+1) -> 14 | T26: =VLOOKUP(Q26,original!B:C,2,FALSE) -> Controlling the Symmetry of Perylene Derivatives via Selective ortho-Borylation | U26: https://doi.org/10.1021/acs.joc.4c02669 | V26: =SUBSTITUTE(SUBSTITUTE(MID(U26,LEN(U26)-8,100),"c.","jo"),"t.","ol") -> jo4c02669 | W26: =B26&"_si_"&R26&".zip" -> jo4c02669_si_001.zip | X26: =IF(U26<>U25,P26,X25&"\t"&P26) -> https://acs.figshare.com/articles/dataset/Controlling_the_Symmetry_of_Perylene_Derivatives_via_Selective_i_ortho_i_-Borylation/28504775 | Y26: =IF(U26<>U27,$Y$1&" --pubDOI "& U26&" --dataDOI """&SUBSTITUTE(U26&X26&"""","https://doi.org/",""),"") -> --localSource c:/temp/acs2/data --targetDir c:/temp/acs2/$DOI$ --noDownload --readOnly --pubDOI https://doi.org/10.1021/acs.joc.4c02669 --dataDOI "10.1021/acs.joc.4c02669https://acs.figshare.com/articles/dataset/Controlling_the_Symmetry_of_Perylene_Derivatives_via_Selective_i_ortho_i_-Borylation/28504775" | Z26: ="<br><a href="""&Q26&""">"&Q26&"</a>" -> <br><a href="https://doi.org/10.1021/acs.joc.4c02669.s001">https://doi.org/10.1021/acs.joc.4c02669.s001</a> | AA26: =IF(AB26="","",MID(AB26,1,LEN(AB26)-4)&".zip") -> jo5c02404_si_002.zip | AB26: jo5c02404_si_002.xyz
A27: 26 | B27: =V27 -> jo4c02676 | C27: =IF(Y27="","",IF(OR(O27,F27=1,M27=""),"#"&B27 &" "&G27,B27&IF(G27="",""," # " &G27))) -> #jo4c02676 XLS | D27: =IF(F27=1,"",IF(AND(D26="",S26=S27),"",S27-SUM(F$2:F26))) | E27: =IF(B27=B26,"1","0") -> 0 | F27: 1 | G27: XLS | M27: =IF(OR(O27,D27=""),"","/*"&D27&" " & B27 &" */"""&Q27&""",//"&T27) | N27: =VLOOKUP(W27,AA:AB,2,FALSE) -> jo4c02676_si_001.xls | O27: =NOT(ISNA(VLOOKUP(W27,AA:AA,1,FALSE))) -> TRUE | P27: https://acs.figshare.com/articles/dataset/Dehydrogenation_of_Aromatic_Alcohols_Aldehydes_and_Ketones_Catalyzed_by_Cu_I_Complexes/28395249 | Q27: https://doi.org/10.1021/acs.joc.4c02676.s001 | R27: =MID(Q27,LEN(Q27)-2,4) -> 001 | S27: =IF(U27=U26,S26,S26+1) -> 15 | T27: =VLOOKUP(Q27,original!B:C,2,FALSE) -> Dehydrogenation of Aromatic Alcohols, Aldehydes, and Ketones Catalyzed by Cu(I) Complexes | U27: https://doi.org/10.1021/acs.joc.4c02676 | V27: =SUBSTITUTE(SUBSTITUTE(MID(U27,LEN(U27)-8,100),"c.","jo"),"t.","ol") -> jo4c02676 | W27: =B27&"_si_"&R27&".zip" -> jo4c02676_si_001.zip | X27: =IF(U27<>U26,P27,X26&"\t"&P27) -> https://acs.figshare.com/articles/dataset/Dehydrogenation_of_Aromatic_Alcohols_Aldehydes_and_Ketones_Catalyzed_by_Cu_I_Complexes/28395249 | Y27: =IF(U27<>U28,$Y$1&" --pubDOI "& U27&" --dataDOI """&SUBSTITUTE(U27&X27&"""","https://doi.org/",""),"") -> --localSource c:/temp/acs2/data --targetDir c:/temp/acs2/$DOI$ --noDownload --readOnly --pubDOI https://doi.org/10.1021/acs.joc.4c02676 --dataDOI "10.1021/acs.joc.4c02676https://acs.figshare.com/articles/dataset/Dehydrogenation_of_Aromatic_Alcohols_Aldehydes_and_Ketones_Catalyzed_by_Cu_I_Complexes/28395249" | Z27: ="<br><a href="""&Q27&""">"&Q27&"</a>" -> <br><a href="https://doi.org/10.1021/acs.joc.4c02676.s001">https://doi.org/10.1021/acs.joc.4c02676.s001</a> | AA27: =IF(AB27="","",MID(AB27,1,LEN(AB27)-4)&".zip") -> jo5c02410_si_002.zip | AB27: jo5c02410_si_002.xyz
